Workbook

Sheet 00_はじめに
A1: 加湿CO2 高速流量切替供給系 — 設計計算書
A2: Humidified-CO2 supply system with 30 ms flow switching — parametric design workbook
B5: 要求仕様 | C5: 出力段: CO2 ガス圧 20 kPa（ゲージ）、温度 20 °C、相対湿度 70 %
C6: 流量: 30 NLPM と 15 NLPM を 30 ms ごとに交互に連続切替
C7: ガス源: 相対湿度 約 90 % の CO2
B9: 使い方 | C9: ① シート『01_入力』の黄色セル（青字）だけを編集する。他は全て数式で連動する。
C10: ② シート『03_湿度状態点』の下部に出る『★必要飽和器温度 T_sat』を読み、01_入力 の『飽和器出口温度』に入れ戻す。
C11: ③ 同シート最下行『S4 で達成される RH と目標との差』が 0 になれば整合が取れている。
C12: ④ 04〜08 の各シートでハードウェア寸法・熱量・安全条件が自動計算される。
C13: ⑤ 『10_検証』が全項目合格であることを確認してから結果を使うこと。
B15: 設計の結論（既定値での要点） | C15: ・出力段の水蒸気モル分率 x_v = 1.374 mol%、露点 14.37 °C、結露余裕は 5.63 K しかない。
C16: ・構成: 一次プレナム(300 kPa abs, 約31 °C) → 臨界ノズル A(常時 15 NLPM) ∥ ノズル B(+15 NLPM, 高速弁) → 出力プレナム(20 °C) → 同期切替排気オリフィス。
C17: ・ノズルのど径は約 0.86 mm × 2 本。背圧比 0.404 で十分にチョークしている。
C18: ・切替素子はサーマル MFC では不可能（最速 300 ms = 周期の5倍）。高速電磁弁（SMC SX10 / Festo MHJ、<1 ms）を使う。
C19: ・『圧力を静かにすること』と『30 ms の流量変調を保つこと』は同じ容積では両立しない。排気側を入口と同期して切り替えることで初めて両立する。
C20: ・最も厳しい制約は温度: dRH/dT = −4.32 %RH/K。±1 %RH を守るには出力段温度を ±0.23 K に制御する必要がある。
B22: 本計算書の特徴（学会発表を意識した点） | C22: ・CO2 を理想気体として扱わない。Z、cp、γ、音速はすべて第2ビリアル展開で実在気体として評価（Span–Wagner に対し 0.2 % 以内）。
C23: ・湿度は CO2 キャリア用のエンハンスメント係数 f で評価している。空気用の Greenspan/CIPM 式は CO2 には使えず、
C24: そのまま使うと RH を 0.93 %RH 過大評価する。f_CO2 = 1.018 に対し f_air = 1.005（121.3 kPa, 20 °C）。
C25: ・f は交差ビリアル係数 B12(H2O–CO2) = −235.5 cm³/mol と、溶存CO2による水の活量低下（IAPWS G7-04）から組み立てている。
C26: ・同じ式に空気の B_aw を入れると CIPM-2007 を 394 ppm 以内で再現する（B_aw = −32.0 cm³/mol は文献値 −30〜−34 の範囲内）。
C27: これが CO2 への外挿を正当化する検証である。残差は第3ビリアル項に由来し、これが本手法の精度の下限を与える。
C28: ・混合比には ε_CO2 = 0.40935 を使用。空気の 0.622 を使うと +51.9 % の誤りになる。
C29: ・NLPM の基準条件を明示（DIN 1343, 0 °C）。20 °C 基準との差は 7.32 % で、良質なノズルの不確かさ 0.2 % の35倍にあたる。
B31: 既知の限界（投稿前に確認すべき事項） | C31: ・本セッションでは外部サイトへの直接アクセス（WebFetch）が遮断されていた。参照値は同じ基準相関を実装する CoolProp 8.0.0 を
C32: ローカル実行して生成し、文献の書誌情報は検索で確認した。投稿前に NIST Webbook / REFPROP で表を再生成して引用すること。
C33: ・B12(H2O–CO2) は Meyer & Harvey (2015) と Wheatley & Harvey (2016 正誤表) の原著値で置き換えること。
C34: 文献のばらつき ±40 cm³/mol は 121 kPa で f に ±0.4 %（RH で ±0.28 %RH）効く。01_入力 の B12 セルで感度を確認できる。
C35: ・ノズルは CO2 で、実機ののど径で校正すること。振動緩和により Cd が最大 2 % ずれる。
C36: ・容量式RHセンサは CO2 に交差感度がある。冷却鏡式（Michell S8000, ±0.1 °C ≈ ±0.42 %RH）を基準とし、CO2 中で校正すること。
C37: ・排気オリフィスの Cd = 0.62 は代表値。実機で校正すること。
B39: 凡例 | C39: 黄色セル＋青字 = 入力値 / 黒字 = 数式 / 赤字＋橙セル = 主要な結果 / 緑字 = 参照値 / 灰色斜体 = 注記・出典

Sheet 01_入力
A1: 入力パラメータ / Input parameters
A2: 黄色セル（青字）のみ編集してください。他のシートはすべてこのシートを参照する数式です。
A4: A. 出力段の目標条件 / Target at the delivery plane
A5: 大気圧 P_atm | B5: 101.325 | C5: kPa | D5: 標準大気圧。実際の設置標高に合わせて変更
A6: 出力段ゲージ圧 P_out,g | B6: 20 | C6: kPa | D6: 要求仕様（ゲージ圧）
A7: 出力段温度 T_out | B7: 20 | C7: °C | D7: 要求仕様
A8: 出力段相対湿度 RH_out | B8: 0.7 | C8: - | D8: 要求仕様（70 %）。RH = p_v /(f·p_sat)
A9: → 出力段絶対圧 P_out,abs | B9: =01_入力!$B$5+01_入力!$B$6 -> 121.325 | C9: kPa | D9: 大気圧 + ゲージ圧
A11: B. ガス源・調湿 / Source gas and humidity conditioning
A12: 一次側（ノズル上流）絶対圧 P_1 | B12: 300 | C12: kPa abs | D12: チョーク維持のため出力段絶対圧の 2.5 倍以上を推奨
A13: 飽和器出口相対湿度 η_sat | B13: 0.9 | C13: - | D13: 「湿度90 %のCO2」＝飽和器の飽和効率。ミスト同伴に注意
A14: 飽和器出口温度 T_sat | B14: 30.655 | C14: °C | D14: ★03シートが算出する『必要飽和器温度』をここに入力
A15: 一次側トレース加熱温度 T_trace | B15: 34 | C15: °C | D15: 一次側配管壁温。加圧側露点（約 28.8 °C）より 5 K 以上高く保つ（US EPA Method 320）
A17: C. 流量と切替タイミング / Flow set-points and switching
A18: 高流量 Q_H | B18: 30 | C18: NLPM
A19: 低流量 Q_L | B19: 15 | C19: NLPM
A20: 高流量保持時間 t_H | B20: 30 | C20: ms | D20: 「30 ms で交互に切替」の解釈。周期 = t_H + t_L
A21: 低流量保持時間 t_L | B21: 30 | C21: ms | D21: 周期を 30 ms とする解釈なら t_H = t_L = 15 ms に変更
A22: 標準状態 基準温度 T_ref | B22: 0 | C22: °C | D22: DIN 1343 = 0 °C（= SEMI E12）。ISO 13443 は 15 °C、20 °C はベンダ慣行
A23: 標準状態 基準圧力 p_ref | B23: 101.325 | C23: kPa | D23: 0 °C 基準と 20 °C 基準では質量流量が 7.32 % 違う
A25: D. ハードウェア / Hardware
A26: 一次プレナム容積 V_1 | B26: 0.5 | C26: L | D26: ノズル上流の安定化容積。p_0 変動は流量誤差に 1:1 で効く
A27: 出力プレナム容積 V_2 | B27: 100 | C27: mL | D27: 出力段の容積。大きいほど圧力は安定するが流量変調が鈍る
A28: 配管内径（切替弁→出力段）d_i | B28: 8 | C28: mm
A29: 配管長（切替弁→出力段）L | B29: 0.025 | C29: m | D29: ★既定値は「弁・ノズル・出力プレナムを 25 mm 以内に一体化する」という推奨構成。05 シートの集中定数限界と整合
A30: 高速弁 応答時間 t_v | B30: 1 | C30: ms | D30: SMC SX10: 0.45/0.40 ms、Festo MHJ10: <1 ms
A31: 入口/出口弁 同期ずれ Δt_skew | B31: 0.5 | C31: ms | D31: ★同期排気方式での残留リプルを決める最重要パラメータ
A32: ポリトロープ指数 n | B32: 1.29 | C32: - | D32: 1 = 等温（遅い）、γ ≈ 1.29 = 断熱（速い）。30 ms なら断熱側
A33: 排気オリフィス 流量係数 Cd_or | B33: 0.62 | C33: - | D33: 薄刃オリフィス。実機では校正すること
A34: プレナム首部 内径 d_neck | B34: 10 | C34: mm | D34: ヘルムホルツ共鳴を切替高調波から外すために使用
A35: プレナム首部 長さ L_neck | B35: 30 | C35: mm
A37: E. 物性モデルの選択 / Property-model options
A38: 交差第2ビリアル係数の補正 ΔB12 (CO2-H2O) | B38: 0 | C38: cm³/mol | D38: ★内蔵相関 B12(T)（20 °C で −235.5、30 °C で −213.4）への加算値。文献ばらつき ±40 の影響を見るのに使う
A39: エンハンスメント係数を適用 (1=する/0=しない) | B39: 1 | C39: - | D39: 0 にすると RH = p_v/p_sat（WMO 定義）になる
A40: CFVN Cd 相関 係数 a | B40: 0.9959 | C40: - | D40: ISO 9300:2022 トロイダル: Cd = a − b·Re^−0.5
A41: CFVN Cd 相関 係数 b | B41: 2.72 | C41: - | D41: 有効範囲 2.1e4 ≤ Re ≤ 3.2e7、u(Cd)=0.3 % (k=2)
A43: F. 安全・換気 / Safety and ventilation
A44: 室容積 V_room | B44: 54 | C44: m³ | D44: 例: 5 × 4 × 2.7 m
A45: CO2 管理濃度 C_limit | B45: 5000 | C45: ppm | D45: ACGIH TLV-TWA / OSHA PEL = 5000 ppm
A46: 外気 CO2 濃度 C_bg | B46: 420 | C46: ppm | D46: 現在の大気中濃度
...

Sheet 02_物性
A1: 物性相関 / Property correlations (reference table)
A2: 本ブックが内部で使う相関式の一覧表。すべて第2ビリアル展開による実在気体評価で、Span–Wagner に対し 0.2 % 以内。
A4: T [°C] | B4: p_sat [Pa] | C4: B_CO2 [cm³/mol] | D4: B12 [cm³/mol] | E4: B_ww [cm³/mol] | F4: Z (1 atm) | G4: Z (300 kPa) | H4: cp [J/mol·K] | I4: γ (1 atm) | J4: μ [µPa·s] | K4: k [mW/m·K] | L4: μ_JT [K/bar] / 音速 [m/s]
A5: -5 | B5: =22064000*EXP(647.096/($A$5+273.15)*(-7.85951783*(1-($A$5+273.15)/647.096)+1.84408259*(1-($A$5+273.15)/647.096)^1.5-11.7866497*(1-($A$5+273.15)/647.096)^3+22.6807411*(1-($A$5+273.15)/647.096)^3.5-15.9618719*(1-($A$5+273.15)/647.096)^4+1.80122502*(1-($A$5+273.15)/647.096)^7.5)) -> 421.81116 | C5: =0.000001*(75.188632-565.620467/(($A$5+273.15)/100)+601.464888/(($A$5+273.15)/100)^2-2018.286032/(($A$5+273.15)/100)^3)*1000000 -> -156.77442 | D5: =0.000001*(-236.26407+204871.53/($A$5+273.15)-59999434/($A$5+273.15)^2)*1000000 -> -306.67884 | E5: =0.000001*(19202.081-20032490/($A$5+273.15)+7075968700/($A$5+273.15)^2-870743060000/($A$5+273.15)^3)*1000000 -> -2256.5057 | F5: =1+0.000001*(75.188632-565.620467/(($A$5+273.15)/100)+601.464888/(($A$5+273.15)/100)^2-2018.286032/(($A$5+273.15)/100)^3)*101325/(8.31446261815324*($A$5+273.15)) -> 0.99287508 | G5: =1+0.000001*(75.188632-565.620467/(($A$5+273.15)/100)+601.464888/(($A$5+273.15)/100)^2-2018.286032/(($A$5+273.15)/100)^3)*300000/(8.31446261815324*($A$5+273.15)) -> 0.97890476 | H5: =(20.823075+0.059235957*($A$5+273.15)-0.00000051159127*($A$5+273.15)^2-0.000000048979736*($A$5+273.15)^3-($A$5+273.15)*0.0000000001*(-1131.240934/(($A$5+273.15)/100)^3+3608.789328/(($A$5+273.15)/100)^4-24219.432384/(($A$5+273.15)/100)^5)*101325) -> 36.170434 | I5: =((20.823075+0.059235957*($A$5+273.15)-0.00000051159127*($A$5+273.15)^2-0.000000048979736*($A$5+273.15)^3-($A$5+273.15)*0.0000000001*(-1131.240934/(($A$5+273.15)/100)^3+3608.789328/(($A$5+273.15)/100)^4-24219.432384/(($A$5+273.15)/100)^5)*101325))/(((20.823075+0.059235957*($A$5+273.15)-0.00000051159127*($A$5+273.15)^2-0.000000048979736*($A$5+273.15)^3)-8.31446261815324-($A$5+273.15)*8.31446261815324*(2*0.00000001*(565.620467/(($A$5+273.15)/100)^2-1202.929776/(($A$5+273.15)/100)^3+6054.858096/(($A$5+273.15)/100)^4)+($A$5+273.15)*0.0000000001*(-1131.240934/(($A$5+273.15)/100)^3+3608.789328/(($A$5+273.15)/100)^4-24219.432384/(($A$5+273.15)/100)^5))*(101325/((1+0.000001*(75.188632-565.620467/(($A$5+273.15)/100)+601.464888/(($A$5+273.15)/100)^2-2018.286032/(($A$5+273.15)/100)^3)*101325/(8.31446261815324*($A$5+273.15)))*8.31446261815324*($A$5+273.15))))) -> 1.3111444 | J5: =0.00000100697*SQRT(($A$5+273.15))/EXP(0.235156-0.491266*LN(($A$5+273.15)/251.196)+0.05211155*LN(($A$5+273.15)/251.196)^2+0.05347906*LN(($A$5+273.15)/251.196)^3-0.01537102*LN(($A$5+273.15)/251.196)^4)*1000000 -> 13.455827 | K5: =0.001*(-2.8088692+0.053424539*($A$5+273.15)+0.000038923913*($A$5+273.15)^2)*1000 -> 14.315722 | L5: =((($A$5+273.15)*0.00000001*(565.620467/(($A$5+273.15)/100)^2-1202.929776/(($A$5+273.15)/100)^3+6054.858096/(($A$5+273.15)/100)^4))-(0.000001*(75.188632-565.620467/(($A$5+273.15)/100)+601.464888/(($A$5+273.15)/100)^2-2018.286032/(($A$5+273.15)/100)^3)))/(20.823075+0.059235957*($A$5+273.15)-0.00000051159127*($A$5+273.15)^2-0.000000048979736*($A$5+273.15)^3)*100000 -> 1.4399663
A6: -2.5 | B6: =22064000*EXP(647.096/($A$6+273.15)*(-7.85951783*(1-($A$6+273.15)/647.096)+1.84408259*(1-($A$6+273.15)/647.096)^1.5-11.7866497*(1-($A$6+273.15)/647.096)^3+22.6807411*(1-($A$6+273.15)/647.096)^3.5-15.9618719*(1-($A$6+273.15)/647.096)^4+1.80122502*(1-($A$6+273.15)/647.096)^7.5)) -> 508.73231 | C6: =0.000001*(75.188632-565.620467/(($A$6+273.15)/100)+601.464888/(($A$6+273.15)/100)^2-2018.286032/(($A$6+273.15)/100)^3)*1000000 -> -153.4902 | D6: =0.000001*(-236.26407+204871.53/($A$6+273.15)-59999434/($A$6+273.15)^2)*1000000 -> -298.39193 | E6: =0.000001*(19202.081-20032490/($A$6+273.15)+7075968700/($A$6+273.15)^2-870743060000/($A$6+273.15)^3)*1000000 -> -2136.1235 | F6: =1+0.000001*(75.188632-565.620467/(($A$6+273.15)/100)+601.464888/(($A$6+273.15)/100)^2-2018.286032/(($A$6+273.15)/100)^3)*101325/(8.31446261815324*($A$6+273.15)) -> 0.99308877 | G6: =1+0.000001*(75.188632-565.620467/(($A$6+273.15)/100)+601.464888/(($A$6+273.15)/100)^2-2018.286032/(($A$6+273.15)/100)^3)*300000/(8.31446261815324*($A$6+273.15)) -> 0.97953745 | H6: =(20.823075+0.059235957*($A$6+273.15)-0.00000051159127*($A$6+273.15)^2-0.000000048979736*($A$6+273.15)^3-($A$6+273.15)*0.0000000001*(-1131.240934/(($A$6+273.15)/100)^3+3608.789328/(($A$6+273.15)/100)^4-24219.432384/(($A$6+273.15)/100)^5)*101325) -> 36.276153 | I6: =((20.823075+0.059235957*($A$6+273.15)-0.00000051159127*($A$6+273.15)^2-0.000000048979736*($A$6+273.15)^3-($A$6+273.15)*0.0000000001*(-1131.240934/(($A$6+273.15)/100)^3+3608.789328/(($A$6+273.15)/100)^4-24219.432384/(($A$6+273.15)/100)^5)*101325))/(((20.823075+0.059235957*($A$6+273.15)-0.00000051159127*($A$6+273.15)^2-0.000000048979736*($A$6+273.15)^3)-8.31446261815324-($A$6+273.15)*8.31446261815324*(2*0.00000001*(565.620467/(($A$6+273.15)/100)^2-1202.929776/(($A$6+273.15)/100)^3+6054.858096/(($A$6+273.15)/100)^4)+($A$6+273.15)*0.0000000001*(-1131.240934/(($A$6+273.15)/100)^3+3608.789328/(($A$6+273.15)/100)^4-24219.432384/(($A$6+273.15)/100)^5))*(101325/((1+0.000001*(75.188632-565.620467/(($A$6+273.15)/100)+601.464888/(($A$6+273.15)/100)^2-2018.286032/(($A$6+273.15)/100)^3)*101325/(8.31446261815324*($A$6+273.15)))*8.31446261815324*($A$6+273.15))))) -> 1.3095772 | J6: =0.00000100697*SQRT(($A$6+273.15))/EXP(0.235156-0.491266*LN(($A$6+273.15)/251.196)+0.05211155*LN(($A$6+273.15)/251.196)^2+0.05347906*LN(($A$6+273.15)/251.196)^3-0.01537102*LN(($A$6+273.15)/251.196)^4)*1000000 -> 13.579161 | K6: =0.001*(-2.8088692+0.053424539*($A$6+273.15)+0.000038923913*($A$6+273.15)^2)*1000 -> 14.501714 | L6: =((($A$6+273.15)*0.00000001*(565.620467/(($A$6+273.15)/100)^2-1202.929776/(($A$6+273.15)/100)^3+6054.858096/(($A$6+273.15)/100)^4))-(0.000001*(75.188632-565.620467/(($A$6+273.15)/100)+601.464888/(($A$6+273.15)/100)^2-2018.286032/(($A$6+273.15)/100)^3)))/(20.823075+0.059235957*($A$6+273.15)-0.00000051159127*($A$6+273.15)^2-0.000000048979736*($A$6+273.15)^3)*100000 -> 1.4050486
A7: 0 | B7: =22064000*EXP(647.096/($A$7+273.15)*(-7.85951783*(1-($A$7+273.15)/647.096)+1.84408259*(1-($A$7+273.15)/647.096)^1.5-11.7866497*(1-($A$7+273.15)/647.096)^3+22.6807411*(1-($A$7+273.15)/647.096)^3.5-15.9618719*(1-($A$7+273.15)/647.096)^4+1.80122502*(1-($A$7+273.15)/647.096)^7.5)) -> 611.21285 | C7: =0.000001*(75.188632-565.620467/(($A$7+273.15)/100)+601.464888/(($A$7+273.15)/100)^2-2018.286032/(($A$7+273.15)/100)^3)*1000000 -> -150.30387 | D7: =0.000001*(-236.26407+204871.53/($A$7+273.15)-59999434/($A$7+273.15)^2)*1000000 -> -290.39523 | E7: =0.000001*(19202.081-20032490/($A$7+273.15)+7075968700/($A$7+273.15)^2-870743060000/($A$7+273.15)^3)*1000000 -> -2023.8921 | F7: =1+0.000001*(75.188632-565.620467/(($A$7+273.15)/100)+601.464888/(($A$7+273.15)/100)^2-2018.286032/(($A$7+273.15)/100)^3)*101325/(8.31446261815324*($A$7+273.15)) -> 0.99329419 | G7: =1+0.000001*(75.188632-565.620467/(($A$7+273.15)/100)+601.464888/(($A$7+273.15)/100)^2-2018.286032/(($A$7+273.15)/100)^3)*300000/(8.31446261815324*($A$7+273.15)) -> 0.98014563 | H7: =(20.823075+0.059235957*($A$7+273.15)-0.00000051159127*($A$7+273.15)^2-0.000000048979736*($A$7+273.15)^3-($A$7+273.15)*0.0000000001*(-1131.240934/(($A$7+273.15)/100)^3+3608.789328/(($A$7+273.15)/100)^4-24219.432384/(($A$7+273.15)/100)^5)*101325) -> 36.382041 | I7: =((20.823075+0.059235957*($A$7+273.15)-0.00000051159127*($A$7+273.15)^2-0.000000048979736*($A$7+273.15)^3-($A$7+273.15)*0.0000000001*(-1131.240934/(($A$7+273.15)/100)^3+3608.789328/(($A$7+273.15)/100)^4-24219.432384/(($A$7+273.15)/100)^5)*101325))/(((20.823075+0.059235957*($A$7+273.15)-0.00000051159127*($A$7+273.15)^2-0.000000048979736*($A$7+273.15)^3)-8.31446261815324-($A$7+273.15)*8.31446261815324*(2*0.00000001*(565.620467/(($A$7+273.15)/100)^2-1202.929776/(($A$7+273.15)/100)^3+6054.858096/(($A$7+273.15)/100)^4)+($A$7+273.15)*0.0000000001*(-1131.240934/(($A$7+273.15)/100)^3+3608.789328/(($A$7+273.15)/100)^4-24219.432384/(($A$7+273.15)/100)^5))*(101325/((1+0.000001*(75.188632-565.620467/(($A$7+273.15)/100)+601.464888/(($A$7+273.15)/100)^2-2018.286032/(($A$7+273.15)/100)^3)*101325/(8.31446261815324*($A$7+273.15)))*8.31446261815324*($A$7+273.15))))) -> 1.3080369 | J7: =0.00000100697*SQRT(($A$7+273.15))/EXP(0.235156-0.491266*LN(($A$7+273.15)/251.196)+0.05211155*LN(($A$7+273.15)/251.196)^2+0.05347906*LN(($A$7+273.15)/251.196)^3-0.01537102*LN(($A$7+273.15)/251.196)^4)*1000000 -> 13.702329 | K7: =0.001*(-2.8088692+0.053424539*($A$7+273.15)+0.000038923913*($A$7+273.15)^2)*1000 -> 14.688193 | L7: =((($A$7+273.15)*0.00000001*(565.620467/(($A$7+273.15)/100)^2-1202.929776/(($A$7+273.15)/100)^3+6054.858096/(($A$7+273.15)/100)^4))-(0.000001*(75.188632-565.620467/(($A$7+273.15)/100)+601.464888/(($A$7+273.15)/100)^2-2018.286032/(($A$7+273.15)/100)^3)))/(20.823075+0.059235957*($A$7+273.15)-0.00000051159127*($A$7+273.15)^2-0.000000048979736*($A$7+273.15)^3)*100000 -> 1.3713917
A8: 2.5 | B8: =22064000*EXP(647.096/($A$8+273.15)*(-7.85951783*(1-($A$8+273.15)/647.096)+1.84408259*(1-($A$8+273.15)/647.096)^1.5-11.7866497*(1-($A$8+273.15)/647.096)^3+22.6807411*(1-($A$8+273.15)/647.096)^3.5-15.9618719*(1-($A$8+273.15)/647.096)^4+1.80122502*(1-($A$8+273.15)/647.096)^7.5)) -> 731.60124 | C8: =0.000001*(75.188632-565.620467/(($A$8+273.15)/100)+601.464888/(($A$8+273.15)/100)^2-2018.286032/(($A$8+273.15)/100)^3)*1000000 -> -147.21127 | D8: =0.000001*(-236.26407+204871.53/($A$8+273.15)-59999434/($A$8+273.15)^2)*1000000 -> -282.67709 | E8: =0.000001*(19202.081-20032490/($A$8+273.15)+7075968700/($A$8+273.15)^2-870743060000/($A$8+273.15)^3)*1000000 -> -1919.2327 | F8: =1+0.000001*(75.188632-565.620467/(($A$8+273.15)/100)+601.464888/(($A$8+273.15)/100)^2-2018.286032/(($A$8+273.15)/100)^3)*101325/(8.31446261815324*($A$8+273.15)) -> 0.99349173 | G8: =1+0.000001*(75.188632-565.620467/(($A$8+273.15)/100)+601.464888/(($A$8+273.15)/100)^2-2018.286032/(($A$8+273.15)/100)^3)*300000/(8.31446261815324*($A$8+273.15)) -> 0.98073051 | H8: =(20.823075+0.059235957*($A$8+273.15)-0.00000051159127*($A$8+273.15)^2-0.000000048979736*($A$8+273.15)^3-($A$8+273.15)*0.0000000001*(-1131.240934/(($A$8+273.15)/100)^3+3608.789328/(($A$8+273.15)/100)^4-24219.432384/(($A$8+273.15)/100)^5)*101325) -> 36.488057 | I8: =((20.823075+0.059235957*($A$8+273.15)-0.00000051159127*($A$8+273.15)^2-0.000000048979736*($A$8+273.15)^3-($A$8+273.15)*0.0000000001*(-1131.240934/(($A$8+273.15)/100)^3+3608.789328/(($A$8+273.15)/100)^4-24219.432384/(($A$8+273.15)/100)^5)*101325))/(((20.823075+0.059235957*($A$8+273.15)-0.00000051159127*($A$8+273.15)^2-0.000000048979736*($A$8+273.15)^3)-8.31446261815324-($A$8+273.15)*8.31446261815324*(2*0.00000001*(565.620467/(($A$8+273.15)/100)^2-1202.929776/(($A$8+273.15)/100)^3+6054.858096/(($A$8+273.15)/100)^4)+($A$8+273.15)*0.0000000001*(-1131.240934/(($A$8+273.15)/100)^3+3608.789328/(($A$8+273.15)/100)^4-24219.432384/(($A$8+273.15)/100)^5))*(101325/((1+0.000001*(75.188632-565.620467/(($A$8+273.15)/100)+601.464888/(($A$8+273.15)/100)^2-2018.286032/(($A$8+273.15)/100)^3)*101325/(8.31446261815324*($A$8+273.15)))*8.31446261815324*($A$8+273.15))))) -> 1.3065226 | J8: =0.00000100697*SQRT(($A$8+273.15))/EXP(0.235156-0.491266*LN(($A$8+273.15)/251.196)+0.05211155*LN(($A$8+273.15)/251.196)^2+0.05347906*LN(($A$8+273.15)/251.196)^3-0.01537102*LN(($A$8+273.15)/251.196)^4)*1000000 -> 13.825327 | K8: =0.001*(-2.8088692+0.053424539*($A$8+273.15)+0.000038923913*($A$8+273.15)^2)*1000 -> 14.875158 | L8: =((($A$8+273.15)*0.00000001*(565.620467/(($A$8+273.15)/100)^2-1202.929776/(($A$8+273.15)/100)^3+6054.858096/(($A$8+273.15)/100)^4))-(0.000001*(75.188632-565.620467/(($A$8+273.15)/100)+601.464888/(($A$8+273.15)/100)^2-2018.286032/(($A$8+273.15)/100)^3)))/(20.823075+0.059235957*($A$8+273.15)-0.00000051159127*($A$8+273.15)^2-0.000000048979736*($A$8+273.15)^3)*100000 -> 1.338937
A9: 5 | B9: =22064000*EXP(647.096/($A$9+273.15)*(-7.85951783*(1-($A$9+273.15)/647.096)+1.84408259*(1-($A$9+273.15)/647.096)^1.5-11.7866497*(1-($A$9+273.15)/647.096)^3+22.6807411*(1-($A$9+273.15)/647.096)^3.5-15.9618719*(1-($A$9+273.15)/647.096)^4+1.80122502*(1-($A$9+273.15)/647.096)^7.5)) -> 872.53022 | C9: =0.000001*(75.188632-565.620467/(($A$9+273.15)/100)+601.464888/(($A$9+273.15)/100)^2-2018.286032/(($A$9+273.15)/100)^3)*1000000 -> -144.2085 | D9: =0.000001*(-236.26407+204871.53/($A$9+273.15)-59999434/($A$9+273.15)^2)*1000000 -> -275.22644 | E9: =0.000001*(19202.081-20032490/($A$9+273.15)+7075968700/($A$9+273.15)^2-870743060000/($A$9+273.15)^3)*1000000 -> -1821.6072 | F9: =1+0.000001*(75.188632-565.620467/(($A$9+273.15)/100)+601.464888/(($A$9+273.15)/100)^2-2018.286032/(($A$9+273.15)/100)^3)*101325/(8.31446261815324*($A$9+273.15)) -> 0.99368179 | G9: =1+0.000001*(75.188632-565.620467/(($A$9+273.15)/100)+601.464888/(($A$9+273.15)/100)^2-2018.286032/(($A$9+273.15)/100)^3)*300000/(8.31446261815324*($A$9+273.15)) -> 0.98129323 | H9: =(20.823075+0.059235957*($A$9+273.15)-0.00000051159127*($A$9+273.15)^2-0.000000048979736*($A$9+273.15)^3-($A$9+273.15)*0.0000000001*(-1131.240934/(($A$9+273.15)/100)^3+3608.789328/(($A$9+273.15)/100)^4-24219.432384/(($A$9+273.15)/100)^5)*101325) -> 36.594161 | I9: =((20.823075+0.059235957*($A$9+273.15)-0.00000051159127*($A$9+273.15)^2-0.000000048979736*($A$9+273.15)^3-($A$9+273.15)*0.0000000001*(-1131.240934/(($A$9+273.15)/100)^3+3608.789328/(($A$9+273.15)/100)^4-24219.432384/(($A$9+273.15)/100)^5)*101325))/(((20.823075+0.059235957*($A$9+273.15)-0.00000051159127*($A$9+273.15)^2-0.000000048979736*($A$9+273.15)^3)-8.31446261815324-($A$9+273.15)*8.31446261815324*(2*0.00000001*(565.620467/(($A$9+273.15)/100)^2-1202.929776/(($A$9+273.15)/100)^3+6054.858096/(($A$9+273.15)/100)^4)+($A$9+273.15)*0.0000000001*(-1131.240934/(($A$9+273.15)/100)^3+3608.789328/(($A$9+273.15)/100)^4-24219.432384/(($A$9+273.15)/100)^5))*(101325/((1+0.000001*(75.188632-565.620467/(($A$9+273.15)/100)+601.464888/(($A$9+273.15)/100)^2-2018.286032/(($A$9+273.15)/100)^3)*101325/(8.31446261815324*($A$9+273.15)))*8.31446261815324*($A$9+273.15))))) -> 1.3050338 | J9: =0.00000100697*SQRT(($A$9+273.15))/EXP(0.235156-0.491266*LN(($A$9+273.15)/251.196)+0.05211155*LN(($A$9+273.15)/251.196)^2+0.05347906*LN(($A$9+273.15)/251.196)^3-0.01537102*LN(($A$9+273.15)/251.196)^4)*1000000 -> 13.948152 | K9: =0.001*(-2.8088692+0.053424539*($A$9+273.15)+0.000038923913*($A$9+273.15)^2)*1000 -> 15.062609 | L9: =((($A$9+273.15)*0.00000001*(565.620467/(($A$9+273.15)/100)^2-1202.929776/(($A$9+273.15)/100)^3+6054.858096/(($A$9+273.15)/100)^4))-(0.000001*(75.188632-565.620467/(($A$9+273.15)/100)+601.464888/(($A$9+273.15)/100)^2-2018.286032/(($A$9+273.15)/100)^3)))/(20.823075+0.059235957*($A$9+273.15)-0.00000051159127*($A$9+273.15)^2-0.000000048979736*($A$9+273.15)^3)*100000 -> 1.3076293
A10: 7.5 | B10: =22064000*EXP(647.096/($A$10+273.15)*(-7.85951783*(1-($A$10+273.15)/647.096)+1.84408259*(1-($A$10+273.15)/647.096)^1.5-11.7866497*(1-($A$10+273.15)/647.096)^3+22.6807411*(1-($A$10+273.15)/647.096)^3.5-15.9618719*(1-($A$10+273.15)/647.096)^4+1.80122502*(1-($A$10+273.15)/647.096)^7.5)) -> 1036.9416 | C10: =0.000001*(75.188632-565.620467/(($A$10+273.15)/100)+601.464888/(($A$10+273.15)/100)^2-2018.286032/(($A$10+273.15)/100)^3)*1000000 -> -141.29184 | D10: =0.000001*(-236.26407+204871.53/($A$10+273.15)-59999434/($A$10+273.15)^2)*1000000 -> -268.03272 | E10: =0.000001*(19202.081-20032490/($A$10+273.15)+7075968700/($A$10+273.15)^2-870743060000/($A$10+273.15)^3)*1000000 -> -1730.5147 | F10: =1+0.000001*(75.188632-565.620467/(($A$10+273.15)/100)+601.464888/(($A$10+273.15)/100)^2-2018.286032/(($A$10+273.15)/100)^3)*101325/(8.31446261815324*($A$10+273.15)) -> 0.99386472 | G10: =1+0.000001*(75.188632-565.620467/(($A$10+273.15)/100)+601.464888/(($A$10+273.15)/100)^2-2018.286032/(($A$10+273.15)/100)^3)*300000/(8.31446261815324*($A$10+273.15)) -> 0.98183485 | H10: =(20.823075+0.059235957*($A$10+273.15)-0.00000051159127*($A$10+273.15)^2-0.000000048979736*($A$10+273.15)^3-($A$10+273.15)*0.0000000001*(-1131.240934/(($A$10+273.15)/100)^3+3608.789328/(($A$10+273.15)/100)^4-24219.432384/(($A$10+273.15)/100)^5)*101325) -> 36.700318 | I10: =((20.823075+0.059235957*($A$10+273.15)-0.00000051159127*($A$10+273.15)^2-0.000000048979736*($A$10+273.15)^3-($A$10+273.15)*0.0000000001*(-1131.240934/(($A$10+273.15)/100)^3+3608.789328/(($A$10+273.15)/100)^4-24219.432384/(($A$10+273.15)/100)^5)*101325))/(((20.823075+0.059235957*($A$10+273.15)-0.00000051159127*($A$10+273.15)^2-0.000000048979736*($A$10+273.15)^3)-8.31446261815324-($A$10+273.15)*8.31446261815324*(2*0.00000001*(565.620467/(($A$10+273.15)/100)^2-1202.929776/(($A$10+273.15)/100)^3+6054.858096/(($A$10+273.15)/100)^4)+($A$10+273.15)*0.0000000001*(-1131.240934/(($A$10+273.15)/100)^3+3608.789328/(($A$10+273.15)/100)^4-24219.432384/(($A$10+273.15)/100)^5))*(101325/((1+0.000001*(75.188632-565.620467/(($A$10+273.15)/100)+601.464888/(($A$10+273.15)/100)^2-2018.286032/(($A$10+273.15)/100)^3)*101325/(8.31446261815324*($A$10+273.15)))*8.31446261815324*($A$10+273.15))))) -> 1.3035698 | J10: =0.00000100697*SQRT(($A$10+273.15))/EXP(0.235156-0.491266*LN(($A$10+273.15)/251.196)+0.05211155*LN(($A$10+273.15)/251.196)^2+0.05347906*LN(($A$10+273.15)/251.196)^3-0.01537102*LN(($A$10+273.15)/251.196)^4)*1000000 -> 14.070802 | K10: =0.001*(-2.8088692+0.053424539*($A$10+273.15)+0.000038923913*($A$10+273.15)^2)*1000 -> 15.250547 | L10: =((($A$10+273.15)*0.00000001*(565.620467/(($A$10+273.15)/100)^2-1202.929776/(($A$10+273.15)/100)^3+6054.858096/(($A$10+273.15)/100)^4))-(0.000001*(75.188632-565.620467/(($A$10+273.15)/100)+601.464888/(($A$10+273.15)/100)^2-2018.286032/(($A$10+273.15)/100)^3)))/(20.823075+0.059235957*($A$10+273.15)-0.00000051159127*($A$10+273.15)^2-0.000000048979736*($A$10+273.15)^3)*100000 -> 1.2774162
A11: 10 | B11: =22064000*EXP(647.096/($A$11+273.15)*(-7.85951783*(1-($A$11+273.15)/647.096)+1.84408259*(1-($A$11+273.15)/647.096)^1.5-11.7866497*(1-($A$11+273.15)/647.096)^3+22.6807411*(1-($A$11+273.15)/647.096)^3.5-15.9618719*(1-($A$11+273.15)/647.096)^4+1.80122502*(1-($A$11+273.15)/647.096)^7.5)) -> 1228.1122 | C11: =0.000001*(75.188632-565.620467/(($A$11+273.15)/100)+601.464888/(($A$11+273.15)/100)^2-2018.286032/(($A$11+273.15)/100)^3)*1000000 -> -138.45776 | D11: =0.000001*(-236.26407+204871.53/($A$11+273.15)-59999434/($A$11+273.15)^2)*1000000 -> -261.08586 | E11: =0.000001*(19202.081-20032490/($A$11+273.15)+7075968700/($A$11+273.15)^2-870743060000/($A$11+273.15)^3)*1000000 -> -1645.4892 | F11: =1+0.000001*(75.188632-565.620467/(($A$11+273.15)/100)+601.464888/(($A$11+273.15)/100)^2-2018.286032/(($A$11+273.15)/100)^3)*101325/(8.31446261815324*($A$11+273.15)) -> 0.99404087 | G11: =1+0.000001*(75.188632-565.620467/(($A$11+273.15)/100)+601.464888/(($A$11+273.15)/100)^2-2018.286032/(($A$11+273.15)/100)^3)*300000/(8.31446261815324*($A$11+273.15)) -> 0.98235638 | H11: =(20.823075+0.059235957*($A$11+273.15)-0.00000051159127*($A$11+273.15)^2-0.000000048979736*($A$11+273.15)^3-($A$11+273.15)*0.0000000001*(-1131.240934/(($A$11+273.15)/100)^3+3608.789328/(($A$11+273.15)/100)^4-24219.432384/(($A$11+273.15)/100)^5)*101325) -> 36.806493 | I11: =((20.823075+0.059235957*($A$11+273.15)-0.00000051159127*($A$11+273.15)^2-0.000000048979736*($A$11+273.15)^3-($A$11+273.15)*0.0000000001*(-1131.240934/(($A$11+273.15)/100)^3+3608.789328/(($A$11+273.15)/100)^4-24219.432384/(($A$11+273.15)/100)^5)*101325))/(((20.823075+0.059235957*($A$11+273.15)-0.00000051159127*($A$11+273.15)^2-0.000000048979736*($A$11+273.15)^3)-8.31446261815324-($A$11+273.15)*8.31446261815324*(2*0.00000001*(565.620467/(($A$11+273.15)/100)^2-1202.929776/(($A$11+273.15)/100)^3+6054.858096/(($A$11+273.15)/100)^4)+($A$11+273.15)*0.0000000001*(-1131.240934/(($A$11+273.15)/100)^3+3608.789328/(($A$11+273.15)/100)^4-24219.432384/(($A$11+273.15)/100)^5))*(101325/((1+0.000001*(75.188632-565.620467/(($A$11+273.15)/100)+601.464888/(($A$11+273.15)/100)^2-2018.286032/(($A$11+273.15)/100)^3)*101325/(8.31446261815324*($A$11+273.15)))*8.31446261815324*($A$11+273.15))))) -> 1.3021298 | J11: =0.00000100697*SQRT(($A$11+273.15))/EXP(0.235156-0.491266*LN(($A$11+273.15)/251.196)+0.05211155*LN(($A$11+273.15)/251.196)^2+0.05347906*LN(($A$11+273.15)/251.196)^3-0.01537102*LN(($A$11+273.15)/251.196)^4)*1000000 -> 14.193274 | K11: =0.001*(-2.8088692+0.053424539*($A$11+273.15)+0.000038923913*($A$11+273.15)^2)*1000 -> 15.438972 | L11: =((($A$11+273.15)*0.00000001*(565.620467/(($A$11+273.15)/100)^2-1202.929776/(($A$11+273.15)/100)^3+6054.858096/(($A$11+273.15)/100)^4))-(0.000001*(75.188632-565.620467/(($A$11+273.15)/100)+601.464888/(($A$11+273.15)/100)^2-2018.286032/(($A$11+273.15)/100)^3)))/(20.823075+0.059235957*($A$11+273.15)-0.00000051159127*($A$11+273.15)^2-0.000000048979736*($A$11+273.15)^3)*100000 -> 1.2482485
A12: 12.5 | B12: =22064000*EXP(647.096/($A$12+273.15)*(-7.85951783*(1-($A$12+273.15)/647.096)+1.84408259*(1-($A$12+273.15)/647.096)^1.5-11.7866497*(1-($A$12+273.15)/647.096)^3+22.6807411*(1-($A$12+273.15)/647.096)^3.5-15.9618719*(1-($A$12+273.15)/647.096)^4+1.80122502*(1-($A$12+273.15)/647.096)^7.5)) -> 1449.6809 | C12: =0.000001*(75.188632-565.620467/(($A$12+273.15)/100)+601.464888/(($A$12+273.15)/100)^2-2018.286032/(($A$12+273.15)/100)^3)*1000000 -> -135.70292 | D12: =0.000001*(-236.26407+204871.53/($A$12+273.15)-59999434/($A$12+273.15)^2)*1000000 -> -254.37627 | E12: =0.000001*(19202.081-20032490/($A$12+273.15)+7075968700/($A$12+273.15)^2-870743060000/($A$12+273.15)^3)*1000000 -> -1566.097 | F12: =1+0.000001*(75.188632-565.620467/(($A$12+273.15)/100)+601.464888/(($A$12+273.15)/100)^2-2018.286032/(($A$12+273.15)/100)^3)*101325/(8.31446261815324*($A$12+273.15)) -> 0.99421055 | G12: =1+0.000001*(75.188632-565.620467/(($A$12+273.15)/100)+601.464888/(($A$12+273.15)/100)^2-2018.286032/(($A$12+273.15)/100)^3)*300000/(8.31446261815324*($A$12+273.15)) -> 0.98285877 | H12: =(20.823075+0.059235957*($A$12+273.15)-0.00000051159127*($A$12+273.15)^2-0.000000048979736*($A$12+273.15)^3-($A$12+273.15)*0.0000000001*(-1131.240934/(($A$12+273.15)/100)^3+3608.789328/(($A$12+273.15)/100)^4-24219.432384/(($A$12+273.15)/100)^5)*101325) -> 36.912652 | I12: =((20.823075+0.059235957*($A$12+273.15)-0.00000051159127*($A$12+273.15)^2-0.000000048979736*($A$12+273.15)^3-($A$12+273.15)*0.0000000001*(-1131.240934/(($A$12+273.15)/100)^3+3608.789328/(($A$12+273.15)/100)^4-24219.432384/(($A$12+273.15)/100)^5)*101325))/(((20.823075+0.059235957*($A$12+273.15)-0.00000051159127*($A$12+273.15)^2-0.000000048979736*($A$12+273.15)^3)-8.31446261815324-($A$12+273.15)*8.31446261815324*(2*0.00000001*(565.620467/(($A$12+273.15)/100)^2-1202.929776/(($A$12+273.15)/100)^3+6054.858096/(($A$12+273.15)/100)^4)+($A$12+273.15)*0.0000000001*(-1131.240934/(($A$12+273.15)/100)^3+3608.789328/(($A$12+273.15)/100)^4-24219.432384/(($A$12+273.15)/100)^5))*(101325/((1+0.000001*(75.188632-565.620467/(($A$12+273.15)/100)+601.464888/(($A$12+273.15)/100)^2-2018.286032/(($A$12+273.15)/100)^3)*101325/(8.31446261815324*($A$12+273.15)))*8.31446261815324*($A$12+273.15))))) -> 1.3007134 | J12: =0.00000100697*SQRT(($A$12+273.15))/EXP(0.235156-0.491266*LN(($A$12+273.15)/251.196)+0.05211155*LN(($A$12+273.15)/251.196)^2+0.05347906*LN(($A$12+273.15)/251.196)^3-0.01537102*LN(($A$12+273.15)/251.196)^4)*1000000 -> 14.315565 | K12: =0.001*(-2.8088692+0.053424539*($A$12+273.15)+0.000038923913*($A$12+273.15)^2)*1000 -> 15.627883 | L12: =((($A$12+273.15)*0.00000001*(565.620467/(($A$12+273.15)/100)^2-1202.929776/(($A$12+273.15)/100)^3+6054.858096/(($A$12+273.15)/100)^4))-(0.000001*(75.188632-565.620467/(($A$12+273.15)/100)+601.464888/(($A$12+273.15)/100)^2-2018.286032/(($A$12+273.15)/100)^3)))/(20.823075+0.059235957*($A$12+273.15)-0.00000051159127*($A$12+273.15)^2-0.000000048979736*($A$12+273.15)^3)*100000 -> 1.2200794
A13: 15 | B13: =22064000*EXP(647.096/($A$13+273.15)*(-7.85951783*(1-($A$13+273.15)/647.096)+1.84408259*(1-($A$13+273.15)/647.096)^1.5-11.7866497*(1-($A$13+273.15)/647.096)^3+22.6807411*(1-($A$13+273.15)/647.096)^3.5-15.9618719*(1-($A$13+273.15)/647.096)^4+1.80122502*(1-($A$13+273.15)/647.096)^7.5)) -> 1705.677 | C13: =0.000001*(75.188632-565.620467/(($A$13+273.15)/100)+601.464888/(($A$13+273.15)/100)^2-2018.286032/(($A$13+273.15)/100)^3)*1000000 -> -133.02414 | D13: =0.000001*(-236.26407+204871.53/($A$13+273.15)-59999434/($A$13+273.15)^2)*1000000 -> -247.89478 | E13: =0.000001*(19202.081-20032490/($A$13+273.15)+7075968700/($A$13+273.15)^2-870743060000/($A$13+273.15)^3)*1000000 -> -1491.9342 | F13: =1+0.000001*(75.188632-565.620467/(($A$13+273.15)/100)+601.464888/(($A$13+273.15)/100)^2-2018.286032/(($A$13+273.15)/100)^3)*101325/(8.31446261815324*($A$13+273.15)) -> 0.99437407 | G13: =1+0.000001*(75.188632-565.620467/(($A$13+273.15)/100)+601.464888/(($A$13+273.15)/100)^2-2018.286032/(($A$13+273.15)/100)^3)*300000/(8.31446261815324*($A$13+273.15)) -> 0.98334292 | H13: =(20.823075+0.059235957*($A$13+273.15)-0.00000051159127*($A$13+273.15)^2-0.000000048979736*($A$13+273.15)^3-($A$13+273.15)*0.0000000001*(-1131.240934/(($A$13+273.15)/100)^3+3608.789328/(($A$13+273.15)/100)^4-24219.432384/(($A$13+273.15)/100)^5)*101325) -> 37.018766 | I13: =((20.823075+0.059235957*($A$13+273.15)-0.00000051159127*($A$13+273.15)^2-0.000000048979736*($A$13+273.15)^3-($A$13+273.15)*0.0000000001*(-1131.240934/(($A$13+273.15)/100)^3+3608.789328/(($A$13+273.15)/100)^4-24219.432384/(($A$13+273.15)/100)^5)*101325))/(((20.823075+0.059235957*($A$13+273.15)-0.00000051159127*($A$13+273.15)^2-0.000000048979736*($A$13+273.15)^3)-8.31446261815324-($A$13+273.15)*8.31446261815324*(2*0.00000001*(565.620467/(($A$13+273.15)/100)^2-1202.929776/(($A$13+273.15)/100)^3+6054.858096/(($A$13+273.15)/100)^4)+($A$13+273.15)*0.0000000001*(-1131.240934/(($A$13+273.15)/100)^3+3608.789328/(($A$13+273.15)/100)^4-24219.432384/(($A$13+273.15)/100)^5))*(101325/((1+0.000001*(75.188632-565.620467/(($A$13+273.15)/100)+601.464888/(($A$13+273.15)/100)^2-2018.286032/(($A$13+273.15)/100)^3)*101325/(8.31446261815324*($A$13+273.15)))*8.31446261815324*($A$13+273.15))))) -> 1.2993198 | J13: =0.00000100697*SQRT(($A$13+273.15))/EXP(0.235156-0.491266*LN(($A$13+273.15)/251.196)+0.05211155*LN(($A$13+273.15)/251.196)^2+0.05347906*LN(($A$13+273.15)/251.196)^3-0.01537102*LN(($A$13+273.15)/251.196)^4)*1000000 -> 14.437675 | K13: =0.001*(-2.8088692+0.053424539*($A$13+273.15)+0.000038923913*($A$13+273.15)^2)*1000 -> 15.817281 | L13: =((($A$13+273.15)*0.00000001*(565.620467/(($A$13+273.15)/100)^2-1202.929776/(($A$13+273.15)/100)^3+6054.858096/(($A$13+273.15)/100)^4))-(0.000001*(75.188632-565.620467/(($A$13+273.15)/100)+601.464888/(($A$13+273.15)/100)^2-2018.286032/(($A$13+273.15)/100)^3)))/(20.823075+0.059235957*($A$13+273.15)-0.00000051159127*($A$13+273.15)^2-0.000000048979736*($A$13+273.15)^3)*100000 -> 1.1928648
A14: 17.5 | B14: =22064000*EXP(647.096/($A$14+273.15)*(-7.85951783*(1-($A$14+273.15)/647.096)+1.84408259*(1-($A$14+273.15)/647.096)^1.5-11.7866497*(1-($A$14+273.15)/647.096)^3+22.6807411*(1-($A$14+273.15)/647.096)^3.5-15.9618719*(1-($A$14+273.15)/647.096)^4+1.80122502*(1-($A$14+273.15)/647.096)^7.5)) -> 2000.5488 | C14: =0.000001*(75.188632-565.620467/(($A$14+273.15)/100)+601.464888/(($A$14+273.15)/100)^2-2018.286032/(($A$14+273.15)/100)^3)*1000000 -> -130.41841 | D14: =0.000001*(-236.26407+204871.53/($A$14+273.15)-59999434/($A$14+273.15)^2)*1000000 -> -241.63265 | E14: =0.000001*(19202.081-20032490/($A$14+273.15)+7075968700/($A$14+273.15)^2-870743060000/($A$14+273.15)^3)*1000000 -> -1422.6245 | F14: =1+0.000001*(75.188632-565.620467/(($A$14+273.15)/100)+601.464888/(($A$14+273.15)/100)^2-2018.286032/(($A$14+273.15)/100)^3)*101325/(8.31446261815324*($A$14+273.15)) -> 0.99453172 | G14: =1+0.000001*(75.188632-565.620467/(($A$14+273.15)/100)+601.464888/(($A$14+273.15)/100)^2-2018.286032/(($A$14+273.15)/100)^3)*300000/(8.31446261815324*($A$14+273.15)) -> 0.98380967 | H14: =(20.823075+0.059235957*($A$14+273.15)-0.00000051159127*($A$14+273.15)^2-0.000000048979736*($A$14+273.15)^3-($A$14+273.15)*0.0000000001*(-1131.240934/(($A$14+273.15)/100)^3+3608.789328/(($A$14+273.15)/100)^4-24219.432384/(($A$14+273.15)/100)^5)*101325) -> 37.124805 | I14: =((20.823075+0.059235957*($A$14+273.15)-0.00000051159127*($A$14+273.15)^2-0.000000048979736*($A$14+273.15)^3-($A$14+273.15)*0.0000000001*(-1131.240934/(($A$14+273.15)/100)^3+3608.789328/(($A$14+273.15)/100)^4-24219.432384/(($A$14+273.15)/100)^5)*101325))/(((20.823075+0.059235957*($A$14+273.15)-0.00000051159127*($A$14+273.15)^2-0.000000048979736*($A$14+273.15)^3)-8.31446261815324-($A$14+273.15)*8.31446261815324*(2*0.00000001*(565.620467/(($A$14+273.15)/100)^2-1202.929776/(($A$14+273.15)/100)^3+6054.858096/(($A$14+273.15)/100)^4)+($A$14+273.15)*0.0000000001*(-1131.240934/(($A$14+273.15)/100)^3+3608.789328/(($A$14+273.15)/100)^4-24219.432384/(($A$14+273.15)/100)^5))*(101325/((1+0.000001*(75.188632-565.620467/(($A$14+273.15)/100)+601.464888/(($A$14+273.15)/100)^2-2018.286032/(($A$14+273.15)/100)^3)*101325/(8.31446261815324*($A$14+273.15)))*8.31446261815324*($A$14+273.15))))) -> 1.2979487 | J14: =0.00000100697*SQRT(($A$14+273.15))/EXP(0.235156-0.491266*LN(($A$14+273.15)/251.196)+0.05211155*LN(($A$14+273.15)/251.196)^2+0.05347906*LN(($A$14+273.15)/251.196)^3-0.01537102*LN(($A$14+273.15)/251.196)^4)*1000000 -> 14.559599 | K14: =0.001*(-2.8088692+0.053424539*($A$14+273.15)+0.000038923913*($A$14+273.15)^2)*1000 -> 16.007165 | L14: =((($A$14+273.15)*0.00000001*(565.620467/(($A$14+273.15)/100)^2-1202.929776/(($A$14+273.15)/100)^3+6054.858096/(($A$14+273.15)/100)^4))-(0.000001*(75.188632-565.620467/(($A$14+273.15)/100)+601.464888/(($A$14+273.15)/100)^2-2018.286032/(($A$14+273.15)/100)^3)))/(20.823075+0.059235957*($A$14+273.15)-0.00000051159127*($A$14+273.15)^2-0.000000048979736*($A$14+273.15)^3)*100000 -> 1.1665628
A15: 20 | B15: =22064000*EXP(647.096/($A$15+273.15)*(-7.85951783*(1-($A$15+273.15)/647.096)+1.84408259*(1-($A$15+273.15)/647.096)^1.5-11.7866497*(1-($A$15+273.15)/647.096)^3+22.6807411*(1-($A$15+273.15)/647.096)^3.5-15.9618719*(1-($A$15+273.15)/647.096)^4+1.80122502*(1-($A$15+273.15)/647.096)^7.5)) -> 2339.1937 | C15: =0.000001*(75.188632-565.620467/(($A$15+273.15)/100)+601.464888/(($A$15+273.15)/100)^2-2018.286032/(($A$15+273.15)/100)^3)*1000000 -> -127.88286 | D15: =0.000001*(-236.26407+204871.53/($A$15+273.15)-59999434/($A$15+273.15)^2)*1000000 -> -235.58153 | E15: =0.000001*(19202.081-20032490/($A$15+273.15)+7075968700/($A$15+273.15)^2-870743060000/($A$15+273.15)^3)*1000000 -> -1357.8178 | F15: =1+0.000001*(75.188632-565.620467/(($A$15+273.15)/100)+601.464888/(($A$15+273.15)/100)^2-2018.286032/(($A$15+273.15)/100)^3)*101325/(8.31446261815324*($A$15+273.15)) -> 0.99468376 | G15: =1+0.000001*(75.188632-565.620467/(($A$15+273.15)/100)+601.464888/(($A$15+273.15)/100)^2-2018.286032/(($A$15+273.15)/100)^3)*300000/(8.31446261815324*($A$15+273.15)) -> 0.98425983 | H15: =(20.823075+0.059235957*($A$15+273.15)-0.00000051159127*($A$15+273.15)^2-0.000000048979736*($A$15+273.15)^3-($A$15+273.15)*0.0000000001*(-1131.240934/(($A$15+273.15)/100)^3+3608.789328/(($A$15+273.15)/100)^4-24219.432384/(($A$15+273.15)/100)^5)*101325) -> 37.23074 | I15: =((20.823075+0.059235957*($A$15+273.15)-0.00000051159127*($A$15+273.15)^2-0.000000048979736*($A$15+273.15)^3-($A$15+273.15)*0.0000000001*(-1131.240934/(($A$15+273.15)/100)^3+3608.789328/(($A$15+273.15)/100)^4-24219.432384/(($A$15+273.15)/100)^5)*101325))/(((20.823075+0.059235957*($A$15+273.15)-0.00000051159127*($A$15+273.15)^2-0.000000048979736*($A$15+273.15)^3)-8.31446261815324-($A$15+273.15)*8.31446261815324*(2*0.00000001*(565.620467/(($A$15+273.15)/100)^2-1202.929776/(($A$15+273.15)/100)^3+6054.858096/(($A$15+273.15)/100)^4)+($A$15+273.15)*0.0000000001*(-1131.240934/(($A$15+273.15)/100)^3+3608.789328/(($A$15+273.15)/100)^4-24219.432384/(($A$15+273.15)/100)^5))*(101325/((1+0.000001*(75.188632-565.620467/(($A$15+273.15)/100)+601.464888/(($A$15+273.15)/100)^2-2018.286032/(($A$15+273.15)/100)^3)*101325/(8.31446261815324*($A$15+273.15)))*8.31446261815324*($A$15+273.15))))) -> 1.2965993 | J15: =0.00000100697*SQRT(($A$15+273.15))/EXP(0.235156-0.491266*LN(($A$15+273.15)/251.196)+0.05211155*LN(($A$15+273.15)/251.196)^2+0.05347906*LN(($A$15+273.15)/251.196)^3-0.01537102*LN(($A$15+273.15)/251.196)^4)*1000000 -> 14.681337 | K15: =0.001*(-2.8088692+0.053424539*($A$15+273.15)+0.000038923913*($A$15+273.15)^2)*1000 -> 16.197536 | L15: =((($A$15+273.15)*0.00000001*(565.620467/(($A$15+273.15)/100)^2-1202.929776/(($A$15+273.15)/100)^3+6054.858096/(($A$15+273.15)/100)^4))-(0.000001*(75.188632-565.620467/(($A$15+273.15)/100)+601.464888/(($A$15+273.15)/100)^2-2018.286032/(($A$15+273.15)/100)^3)))/(20.823075+0.059235957*($A$15+273.15)-0.00000051159127*($A$15+273.15)^2-0.000000048979736*($A$15+273.15)^3)*100000 -> 1.1411338
A16: 22.5 | B16: =22064000*EXP(647.096/($A$16+273.15)*(-7.85951783*(1-($A$16+273.15)/647.096)+1.84408259*(1-($A$16+273.15)/647.096)^1.5-11.7866497*(1-($A$16+273.15)/647.096)^3+22.6807411*(1-($A$16+273.15)/647.096)^3.5-15.9618719*(1-($A$16+273.15)/647.096)^4+1.80122502*(1-($A$16+273.15)/647.096)^7.5)) -> 2726.9893 | C16: =0.000001*(75.188632-565.620467/(($A$16+273.15)/100)+601.464888/(($A$16+273.15)/100)^2-2018.286032/(($A$16+273.15)/100)^3)*1000000 -> -125.41476 | D16: =0.000001*(-236.26407+204871.53/($A$16+273.15)-59999434/($A$16+273.15)^2)*1000000 -> -229.73346 | E16: =0.000001*(19202.081-20032490/($A$16+273.15)+7075968700/($A$16+273.15)^2-870743060000/($A$16+273.15)^3)*1000000 -> -1297.1875 | F16: =1+0.000001*(75.188632-565.620467/(($A$16+273.15)/100)+601.464888/(($A$16+273.15)/100)^2-2018.286032/(($A$16+273.15)/100)^3)*101325/(8.31446261815324*($A$16+273.15)) -> 0.99483044 | G16: =1+0.000001*(75.188632-565.620467/(($A$16+273.15)/100)+601.464888/(($A$16+273.15)/100)^2-2018.286032/(($A$16+273.15)/100)^3)*300000/(8.31446261815324*($A$16+273.15)) -> 0.98469414 | H16: =(20.823075+0.059235957*($A$16+273.15)-0.00000051159127*($A$16+273.15)^2-0.000000048979736*($A$16+273.15)^3-($A$16+273.15)*0.0000000001*(-1131.240934/(($A$16+273.15)/100)^3+3608.789328/(($A$16+273.15)/100)^4-24219.432384/(($A$16+273.15)/100)^5)*101325) -> 37.336545 | I16: =((20.823075+0.059235957*($A$16+273.15)-0.00000051159127*($A$16+273.15)^2-0.000000048979736*($A$16+273.15)^3-($A$16+273.15)*0.0000000001*(-1131.240934/(($A$16+273.15)/100)^3+3608.789328/(($A$16+273.15)/100)^4-24219.432384/(($A$16+273.15)/100)^5)*101325))/(((20.823075+0.059235957*($A$16+273.15)-0.00000051159127*($A$16+273.15)^2-0.000000048979736*($A$16+273.15)^3)-8.31446261815324-($A$16+273.15)*8.31446261815324*(2*0.00000001*(565.620467/(($A$16+273.15)/100)^2-1202.929776/(($A$16+273.15)/100)^3+6054.858096/(($A$16+273.15)/100)^4)+($A$16+273.15)*0.0000000001*(-1131.240934/(($A$16+273.15)/100)^3+3608.789328/(($A$16+273.15)/100)^4-24219.432384/(($A$16+273.15)/100)^5))*(101325/((1+0.000001*(75.188632-565.620467/(($A$16+273.15)/100)+601.464888/(($A$16+273.15)/100)^2-2018.286032/(($A$16+273.15)/100)^3)*101325/(8.31446261815324*($A$16+273.15)))*8.31446261815324*($A$16+273.15))))) -> 1.2952713 | J16: =0.00000100697*SQRT(($A$16+273.15))/EXP(0.235156-0.491266*LN(($A$16+273.15)/251.196)+0.05211155*LN(($A$16+273.15)/251.196)^2+0.05347906*LN(($A$16+273.15)/251.196)^3-0.01537102*LN(($A$16+273.15)/251.196)^4)*1000000 -> 14.802886 | K16: =0.001*(-2.8088692+0.053424539*($A$16+273.15)+0.000038923913*($A$16+273.15)^2)*1000 -> 16.388393 | L16: =((($A$16+273.15)*0.00000001*(565.620467/(($A$16+273.15)/100)^2-1202.929776/(($A$16+273.15)/100)^3+6054.858096/(($A$16+273.15)/100)^4))-(0.000001*(75.188632-565.620467/(($A$16+273.15)/100)+601.464888/(($A$16+273.15)/100)^2-2018.286032/(($A$16+273.15)/100)^3)))/(20.823075+0.059235957*($A$16+273.15)-0.00000051159127*($A$16+273.15)^2-0.000000048979736*($A$16+273.15)^3)*100000 -> 1.1165402
A17: 25 | B17: =22064000*EXP(647.096/($A$17+273.15)*(-7.85951783*(1-($A$17+273.15)/647.096)+1.84408259*(1-($A$17+273.15)/647.096)^1.5-11.7866497*(1-($A$17+273.15)/647.096)^3+22.6807411*(1-($A$17+273.15)/647.096)^3.5-15.9618719*(1-($A$17+273.15)/647.096)^4+1.80122502*(1-($A$17+273.15)/647.096)^7.5)) -> 3169.8245 | C17: =0.000001*(75.188632-565.620467/(($A$17+273.15)/100)+601.464888/(($A$17+273.15)/100)^2-2018.286032/(($A$17+273.15)/100)^3)*1000000 -> -123.01152 | D17: =0.000001*(-236.26407+204871.53/($A$17+273.15)-59999434/($A$17+273.15)^2)*1000000 -> -224.0808 | E17: =0.000001*(19202.081-20032490/($A$17+273.15)+7075968700/($A$17+273.15)^2-870743060000/($A$17+273.15)^3)*1000000 -> -1240.4295 | F17: =1+0.000001*(75.188632-565.620467/(($A$17+273.15)/100)+601.464888/(($A$17+273.15)/100)^2-2018.286032/(($A$17+273.15)/100)^3)*101325/(8.31446261815324*($A$17+273.15)) -> 0.99497202 | G17: =1+0.000001*(75.188632-565.620467/(($A$17+273.15)/100)+601.464888/(($A$17+273.15)/100)^2-2018.286032/(($A$17+273.15)/100)^3)*300000/(8.31446261815324*($A$17+273.15)) -> 0.98511331 | H17: =(20.823075+0.059235957*($A$17+273.15)-0.00000051159127*($A$17+273.15)^2-0.000000048979736*($A$17+273.15)^3-($A$17+273.15)*0.0000000001*(-1131.240934/(($A$17+273.15)/100)^3+3608.789328/(($A$17+273.15)/100)^4-24219.432384/(($A$17+273.15)/100)^5)*101325) -> 37.442195 | I17: =((20.823075+0.059235957*($A$17+273.15)-0.00000051159127*($A$17+273.15)^2-0.000000048979736*($A$17+273.15)^3-($A$17+273.15)*0.0000000001*(-1131.240934/(($A$17+273.15)/100)^3+3608.789328/(($A$17+273.15)/100)^4-24219.432384/(($A$17+273.15)/100)^5)*101325))/(((20.823075+0.059235957*($A$17+273.15)-0.00000051159127*($A$17+273.15)^2-0.000000048979736*($A$17+273.15)^3)-8.31446261815324-($A$17+273.15)*8.31446261815324*(2*0.00000001*(565.620467/(($A$17+273.15)/100)^2-1202.929776/(($A$17+273.15)/100)^3+6054.858096/(($A$17+273.15)/100)^4)+($A$17+273.15)*0.0000000001*(-1131.240934/(($A$17+273.15)/100)^3+3608.789328/(($A$17+273.15)/100)^4-24219.432384/(($A$17+273.15)/100)^5))*(101325/((1+0.000001*(75.188632-565.620467/(($A$17+273.15)/100)+601.464888/(($A$17+273.15)/100)^2-2018.286032/(($A$17+273.15)/100)^3)*101325/(8.31446261815324*($A$17+273.15)))*8.31446261815324*($A$17+273.15))))) -> 1.2939641 | J17: =0.00000100697*SQRT(($A$17+273.15))/EXP(0.235156-0.491266*LN(($A$17+273.15)/251.196)+0.05211155*LN(($A$17+273.15)/251.196)^2+0.05347906*LN(($A$17+273.15)/251.196)^3-0.01537102*LN(($A$17+273.15)/251.196)^4)*1000000 -> 14.924243 | K17: =0.001*(-2.8088692+0.053424539*($A$17+273.15)+0.000038923913*($A$17+273.15)^2)*1000 -> 16.579737 | L17: =((($A$17+273.15)*0.00000001*(565.620467/(($A$17+273.15)/100)^2-1202.929776/(($A$17+273.15)/100)^3+6054.858096/(($A$17+273.15)/100)^4))-(0.000001*(75.188632-565.620467/(($A$17+273.15)/100)+601.464888/(($A$17+273.15)/100)^2-2018.286032/(($A$17+273.15)/100)^3)))/(20.823075+0.059235957*($A$17+273.15)-0.00000051159127*($A$17+273.15)^2-0.000000048979736*($A$17+273.15)^3)*100000 -> 1.0927465
A18: 27.5 | B18: =22064000*EXP(647.096/($A$18+273.15)*(-7.85951783*(1-($A$18+273.15)/647.096)+1.84408259*(1-($A$18+273.15)/647.096)^1.5-11.7866497*(1-($A$18+273.15)/647.096)^3+22.6807411*(1-($A$18+273.15)/647.096)^3.5-15.9618719*(1-($A$18+273.15)/647.096)^4+1.80122502*(1-($A$18+273.15)/647.096)^7.5)) -> 3674.1317 | C18: =0.000001*(75.188632-565.620467/(($A$18+273.15)/100)+601.464888/(($A$18+273.15)/100)^2-2018.286032/(($A$18+273.15)/100)^3)*1000000 -> -120.67068 | D18: =0.000001*(-236.26407+204871.53/($A$18+273.15)-59999434/($A$18+273.15)^2)*1000000 -> -218.61628 | E18: =0.000001*(19202.081-20032490/($A$18+273.15)+7075968700/($A$18+273.15)^2-870743060000/($A$18+273.15)^3)*1000000 -> -1187.2604 | F18: =1+0.000001*(75.188632-565.620467/(($A$18+273.15)/100)+601.464888/(($A$18+273.15)/100)^2-2018.286032/(($A$18+273.15)/100)^3)*101325/(8.31446261815324*($A$18+273.15)) -> 0.99510872 | G18: =1+0.000001*(75.188632-565.620467/(($A$18+273.15)/100)+601.464888/(($A$18+273.15)/100)^2-2018.286032/(($A$18+273.15)/100)^3)*300000/(8.31446261815324*($A$18+273.15)) -> 0.98551803 | H18: =(20.823075+0.059235957*($A$18+273.15)-0.00000051159127*($A$18+273.15)^2-0.000000048979736*($A$18+273.15)^3-($A$18+273.15)*0.0000000001*(-1131.240934/(($A$18+273.15)/100)^3+3608.789328/(($A$18+273.15)/100)^4-24219.432384/(($A$18+273.15)/100)^5)*101325) -> 37.547666 | I18: =((20.823075+0.059235957*($A$18+273.15)-0.00000051159127*($A$18+273.15)^2-0.000000048979736*($A$18+273.15)^3-($A$18+273.15)*0.0000000001*(-1131.240934/(($A$18+273.15)/100)^3+3608.789328/(($A$18+273.15)/100)^4-24219.432384/(($A$18+273.15)/100)^5)*101325))/(((20.823075+0.059235957*($A$18+273.15)-0.00000051159127*($A$18+273.15)^2-0.000000048979736*($A$18+273.15)^3)-8.31446261815324-($A$18+273.15)*8.31446261815324*(2*0.00000001*(565.620467/(($A$18+273.15)/100)^2-1202.929776/(($A$18+273.15)/100)^3+6054.858096/(($A$18+273.15)/100)^4)+($A$18+273.15)*0.0000000001*(-1131.240934/(($A$18+273.15)/100)^3+3608.789328/(($A$18+273.15)/100)^4-24219.432384/(($A$18+273.15)/100)^5))*(101325/((1+0.000001*(75.188632-565.620467/(($A$18+273.15)/100)+601.464888/(($A$18+273.15)/100)^2-2018.286032/(($A$18+273.15)/100)^3)*101325/(8.31446261815324*($A$18+273.15)))*8.31446261815324*($A$18+273.15))))) -> 1.2926772 | J18: =0.00000100697*SQRT(($A$18+273.15))/EXP(0.235156-0.491266*LN(($A$18+273.15)/251.196)+0.05211155*LN(($A$18+273.15)/251.196)^2+0.05347906*LN(($A$18+273.15)/251.196)^3-0.01537102*LN(($A$18+273.15)/251.196)^4)*1000000 -> 15.045408 | K18: =0.001*(-2.8088692+0.053424539*($A$18+273.15)+0.000038923913*($A$18+273.15)^2)*1000 -> 16.771567 | L18: =((($A$18+273.15)*0.00000001*(565.620467/(($A$18+273.15)/100)^2-1202.929776/(($A$18+273.15)/100)^3+6054.858096/(($A$18+273.15)/100)^4))-(0.000001*(75.188632-565.620467/(($A$18+273.15)/100)+601.464888/(($A$18+273.15)/100)^2-2018.286032/(($A$18+273.15)/100)^3)))/(20.823075+0.059235957*($A$18+273.15)-0.00000051159127*($A$18+273.15)^2-0.000000048979736*($A$18+273.15)^3)*100000 -> 1.0697187
A19: 30 | B19: =22064000*EXP(647.096/($A$19+273.15)*(-7.85951783*(1-($A$19+273.15)/647.096)+1.84408259*(1-($A$19+273.15)/647.096)^1.5-11.7866497*(1-($A$19+273.15)/647.096)^3+22.6807411*(1-($A$19+273.15)/647.096)^3.5-15.9618719*(1-($A$19+273.15)/647.096)^4+1.80122502*(1-($A$19+273.15)/647.096)^7.5)) -> 4246.9199 | C19: =0.000001*(75.188632-565.620467/(($A$19+273.15)/100)+601.464888/(($A$19+273.15)/100)^2-2018.286032/(($A$19+273.15)/100)^3)*1000000 -> -118.38987 | D19: =0.000001*(-236.26407+204871.53/($A$19+273.15)-59999434/($A$19+273.15)^2)*1000000 -> -213.33293 | E19: =0.000001*(19202.081-20032490/($A$19+273.15)+7075968700/($A$19+273.15)^2-870743060000/($A$19+273.15)^3)*1000000 -> -1137.4158 | F19: =1+0.000001*(75.188632-565.620467/(($A$19+273.15)/100)+601.464888/(($A$19+273.15)/100)^2-2018.286032/(($A$19+273.15)/100)^3)*101325/(8.31446261815324*($A$19+273.15)) -> 0.99524074 | G19: =1+0.000001*(75.188632-565.620467/(($A$19+273.15)/100)+601.464888/(($A$19+273.15)/100)^2-2018.286032/(($A$19+273.15)/100)^3)*300000/(8.31446261815324*($A$19+273.15)) -> 0.98590893 | H19: =(20.823075+0.059235957*($A$19+273.15)-0.00000051159127*($A$19+273.15)^2-0.000000048979736*($A$19+273.15)^3-($A$19+273.15)*0.0000000001*(-1131.240934/(($A$19+273.15)/100)^3+3608.789328/(($A$19+273.15)/100)^4-24219.432384/(($A$19+273.15)/100)^5)*101325) -> 37.652935 | I19: =((20.823075+0.059235957*($A$19+273.15)-0.00000051159127*($A$19+273.15)^2-0.000000048979736*($A$19+273.15)^3-($A$19+273.15)*0.0000000001*(-1131.240934/(($A$19+273.15)/100)^3+3608.789328/(($A$19+273.15)/100)^4-24219.432384/(($A$19+273.15)/100)^5)*101325))/(((20.823075+0.059235957*($A$19+273.15)-0.00000051159127*($A$19+273.15)^2-0.000000048979736*($A$19+273.15)^3)-8.31446261815324-($A$19+273.15)*8.31446261815324*(2*0.00000001*(565.620467/(($A$19+273.15)/100)^2-1202.929776/(($A$19+273.15)/100)^3+6054.858096/(($A$19+273.15)/100)^4)+($A$19+273.15)*0.0000000001*(-1131.240934/(($A$19+273.15)/100)^3+3608.789328/(($A$19+273.15)/100)^4-24219.432384/(($A$19+273.15)/100)^5))*(101325/((1+0.000001*(75.188632-565.620467/(($A$19+273.15)/100)+601.464888/(($A$19+273.15)/100)^2-2018.286032/(($A$19+273.15)/100)^3)*101325/(8.31446261815324*($A$19+273.15)))*8.31446261815324*($A$19+273.15))))) -> 1.2914102 | J19: =0.00000100697*SQRT(($A$19+273.15))/EXP(0.235156-0.491266*LN(($A$19+273.15)/251.196)+0.05211155*LN(($A$19+273.15)/251.196)^2+0.05347906*LN(($A$19+273.15)/251.196)^3-0.01537102*LN(($A$19+273.15)/251.196)^4)*1000000 -> 15.166378 | K19: =0.001*(-2.8088692+0.053424539*($A$19+273.15)+0.000038923913*($A$19+273.15)^2)*1000 -> 16.963884 | L19: =((($A$19+273.15)*0.00000001*(565.620467/(($A$19+273.15)/100)^2-1202.929776/(($A$19+273.15)/100)^3+6054.858096/(($A$19+273.15)/100)^4))-(0.000001*(75.188632-565.620467/(($A$19+273.15)/100)+601.464888/(($A$19+273.15)/100)^2-2018.286032/(($A$19+273.15)/100)^3)))/(20.823075+0.059235957*($A$19+273.15)-0.00000051159127*($A$19+273.15)^2-0.000000048979736*($A$19+273.15)^3)*100000 -> 1.047425
A20: 32.5 | B20: =22064000*EXP(647.096/($A$20+273.15)*(-7.85951783*(1-($A$20+273.15)/647.096)+1.84408259*(1-($A$20+273.15)/647.096)^1.5-11.7866497*(1-($A$20+273.15)/647.096)^3+22.6807411*(1-($A$20+273.15)/647.096)^3.5-15.9618719*(1-($A$20+273.15)/647.096)^4+1.80122502*(1-($A$20+273.15)/647.096)^7.5)) -> 4895.8078 | C20: =0.000001*(75.188632-565.620467/(($A$20+273.15)/100)+601.464888/(($A$20+273.15)/100)^2-2018.286032/(($A$20+273.15)/100)^3)*1000000 -> -116.16688 | D20: =0.000001*(-236.26407+204871.53/($A$20+273.15)-59999434/($A$20+273.15)^2)*1000000 -> -208.22409 | E20: =0.000001*(19202.081-20032490/($A$20+273.15)+7075968700/($A$20+273.15)^2-870743060000/($A$20+273.15)^3)*1000000 -> -1090.6494 | F20: =1+0.000001*(75.188632-565.620467/(($A$20+273.15)/100)+601.464888/(($A$20+273.15)/100)^2-2018.286032/(($A$20+273.15)/100)^3)*101325/(8.31446261815324*($A$20+273.15)) -> 0.9953683 | G20: =1+0.000001*(75.188632-565.620467/(($A$20+273.15)/100)+601.464888/(($A$20+273.15)/100)^2-2018.286032/(($A$20+273.15)/100)^3)*300000/(8.31446261815324*($A$20+273.15)) -> 0.98628661 | H20: =(20.823075+0.059235957*($A$20+273.15)-0.00000051159127*($A$20+273.15)^2-0.000000048979736*($A$20+273.15)^3-($A$20+273.15)*0.0000000001*(-1131.240934/(($A$20+273.15)/100)^3+3608.789328/(($A$20+273.15)/100)^4-24219.432384/(($A$20+273.15)/100)^5)*101325) -> 37.757979 | I20: =((20.823075+0.059235957*($A$20+273.15)-0.00000051159127*($A$20+273.15)^2-0.000000048979736*($A$20+273.15)^3-($A$20+273.15)*0.0000000001*(-1131.240934/(($A$20+273.15)/100)^3+3608.789328/(($A$20+273.15)/100)^4-24219.432384/(($A$20+273.15)/100)^5)*101325))/(((20.823075+0.059235957*($A$20+273.15)-0.00000051159127*($A$20+273.15)^2-0.000000048979736*($A$20+273.15)^3)-8.31446261815324-($A$20+273.15)*8.31446261815324*(2*0.00000001*(565.620467/(($A$20+273.15)/100)^2-1202.929776/(($A$20+273.15)/100)^3+6054.858096/(($A$20+273.15)/100)^4)+($A$20+273.15)*0.0000000001*(-1131.240934/(($A$20+273.15)/100)^3+3608.789328/(($A$20+273.15)/100)^4-24219.432384/(($A$20+273.15)/100)^5))*(101325/((1+0.000001*(75.188632-565.620467/(($A$20+273.15)/100)+601.464888/(($A$20+273.15)/100)^2-2018.286032/(($A$20+273.15)/100)^3)*101325/(8.31446261815324*($A$20+273.15)))*8.31446261815324*($A$20+273.15))))) -> 1.2901627 | J20: =0.00000100697*SQRT(($A$20+273.15))/EXP(0.235156-0.491266*LN(($A$20+273.15)/251.196)+0.05211155*LN(($A$20+273.15)/251.196)^2+0.05347906*LN(($A$20+273.15)/251.196)^3-0.01537102*LN(($A$20+273.15)/251.196)^4)*1000000 -> 15.287152 | K20: =0.001*(-2.8088692+0.053424539*($A$20+273.15)+0.000038923913*($A$20+273.15)^2)*1000 -> 17.156688 | L20: =((($A$20+273.15)*0.00000001*(565.620467/(($A$20+273.15)/100)^2-1202.929776/(($A$20+273.15)/100)^3+6054.858096/(($A$20+273.15)/100)^4))-(0.000001*(75.188632-565.620467/(($A$20+273.15)/100)+601.464888/(($A$20+273.15)/100)^2-2018.286032/(($A$20+273.15)/100)^3)))/(20.823075+0.059235957*($A$20+273.15)-0.00000051159127*($A$20+273.15)^2-0.000000048979736*($A$20+273.15)^3)*100000 -> 1.0258347
A21: 35 | B21: =22064000*EXP(647.096/($A$21+273.15)*(-7.85951783*(1-($A$21+273.15)/647.096)+1.84408259*(1-($A$21+273.15)/647.096)^1.5-11.7866497*(1-($A$21+273.15)/647.096)^3+22.6807411*(1-($A$21+273.15)/647.096)^3.5-15.9618719*(1-($A$21+273.15)/647.096)^4+1.80122502*(1-($A$21+273.15)/647.096)^7.5)) -> 5629.0574 | C21: =0.000001*(75.188632-565.620467/(($A$21+273.15)/100)+601.464888/(($A$21+273.15)/100)^2-2018.286032/(($A$21+273.15)/100)^3)*1000000 -> -113.99955 | D21: =0.000001*(-236.26407+204871.53/($A$21+273.15)-59999434/($A$21+273.15)^2)*1000000 -> -203.28338 | E21: =0.000001*(19202.081-20032490/($A$21+273.15)+7075968700/($A$21+273.15)^2-870743060000/($A$21+273.15)^3)*1000000 -> -1046.7315 | F21: =1+0.000001*(75.188632-565.620467/(($A$21+273.15)/100)+601.464888/(($A$21+273.15)/100)^2-2018.286032/(($A$21+273.15)/100)^3)*101325/(8.31446261815324*($A$21+273.15)) -> 0.99549159 | G21: =1+0.000001*(75.188632-565.620467/(($A$21+273.15)/100)+601.464888/(($A$21+273.15)/100)^2-2018.286032/(($A$21+273.15)/100)^3)*300000/(8.31446261815324*($A$21+273.15)) -> 0.98665164 | H21: =(20.823075+0.059235957*($A$21+273.15)-0.00000051159127*($A$21+273.15)^2-0.000000048979736*($A$21+273.15)^3-($A$21+273.15)*0.0000000001*(-1131.240934/(($A$21+273.15)/100)^3+3608.789328/(($A$21+273.15)/100)^4-24219.432384/(($A$21+273.15)/100)^5)*101325) -> 37.862779 | I21: =((20.823075+0.059235957*($A$21+273.15)-0.00000051159127*($A$21+273.15)^2-0.000000048979736*($A$21+273.15)^3-($A$21+273.15)*0.0000000001*(-1131.240934/(($A$21+273.15)/100)^3+3608.789328/(($A$21+273.15)/100)^4-24219.432384/(($A$21+273.15)/100)^5)*101325))/(((20.823075+0.059235957*($A$21+273.15)-0.00000051159127*($A$21+273.15)^2-0.000000048979736*($A$21+273.15)^3)-8.31446261815324-($A$21+273.15)*8.31446261815324*(2*0.00000001*(565.620467/(($A$21+273.15)/100)^2-1202.929776/(($A$21+273.15)/100)^3+6054.858096/(($A$21+273.15)/100)^4)+($A$21+273.15)*0.0000000001*(-1131.240934/(($A$21+273.15)/100)^3+3608.789328/(($A$21+273.15)/100)^4-24219.432384/(($A$21+273.15)/100)^5))*(101325/((1+0.000001*(75.188632-565.620467/(($A$21+273.15)/100)+601.464888/(($A$21+273.15)/100)^2-2018.286032/(($A$21+273.15)/100)^3)*101325/(8.31446261815324*($A$21+273.15)))*8.31446261815324*($A$21+273.15))))) -> 1.2889342 | J21: =0.00000100697*SQRT(($A$21+273.15))/EXP(0.235156-0.491266*LN(($A$21+273.15)/251.196)+0.05211155*LN(($A$21+273.15)/251.196)^2+0.05347906*LN(($A$21+273.15)/251.196)^3-0.01537102*LN(($A$21+273.15)/251.196)^4)*1000000 -> 15.407727 | K21: =0.001*(-2.8088692+0.053424539*($A$21+273.15)+0.000038923913*($A$21+273.15)^2)*1000 -> 17.349978 | L21: =((($A$21+273.15)*0.00000001*(565.620467/(($A$21+273.15)/100)^2-1202.929776/(($A$21+273.15)/100)^3+6054.858096/(($A$21+273.15)/100)^4))-(0.000001*(75.188632-565.620467/(($A$21+273.15)/100)+601.464888/(($A$21+273.15)/100)^2-2018.286032/(($A$21+273.15)/100)^3)))/(20.823075+0.059235957*($A$21+273.15)-0.00000051159127*($A$21+273.15)^2-0.000000048979736*($A$21+273.15)^3)*100000 -> 1.0049191
A22: 37.5 | B22: =22064000*EXP(647.096/($A$22+273.15)*(-7.85951783*(1-($A$22+273.15)/647.096)+1.84408259*(1-($A$22+273.15)/647.096)^1.5-11.7866497*(1-($A$22+273.15)/647.096)^3+22.6807411*(1-($A$22+273.15)/647.096)^3.5-15.9618719*(1-($A$22+273.15)/647.096)^4+1.80122502*(1-($A$22+273.15)/647.096)^7.5)) -> 6455.608 | C22: =0.000001*(75.188632-565.620467/(($A$22+273.15)/100)+601.464888/(($A$22+273.15)/100)^2-2018.286032/(($A$22+273.15)/100)^3)*1000000 -> -111.88586 | D22: =0.000001*(-236.26407+204871.53/($A$22+273.15)-59999434/($A$22+273.15)^2)*1000000 -> -198.50472 | E22: =0.000001*(19202.081-20032490/($A$22+273.15)+7075968700/($A$22+273.15)^2-870743060000/($A$22+273.15)^3)*1000000 -> -1005.4479 | F22: =1+0.000001*(75.188632-565.620467/(($A$22+273.15)/100)+601.464888/(($A$22+273.15)/100)^2-2018.286032/(($A$22+273.15)/100)^3)*101325/(8.31446261815324*($A$22+273.15)) -> 0.99561079 | G22: =1+0.000001*(75.188632-565.620467/(($A$22+273.15)/100)+601.464888/(($A$22+273.15)/100)^2-2018.286032/(($A$22+273.15)/100)^3)*300000/(8.31446261815324*($A$22+273.15)) -> 0.98700456 | H22: =(20.823075+0.059235957*($A$22+273.15)-0.00000051159127*($A$22+273.15)^2-0.000000048979736*($A$22+273.15)^3-($A$22+273.15)*0.0000000001*(-1131.240934/(($A$22+273.15)/100)^3+3608.789328/(($A$22+273.15)/100)^4-24219.432384/(($A$22+273.15)/100)^5)*101325) -> 37.967313 | I22: =((20.823075+0.059235957*($A$22+273.15)-0.00000051159127*($A$22+273.15)^2-0.000000048979736*($A$22+273.15)^3-($A$22+273.15)*0.0000000001*(-1131.240934/(($A$22+273.15)/100)^3+3608.789328/(($A$22+273.15)/100)^4-24219.432384/(($A$22+273.15)/100)^5)*101325))/(((20.823075+0.059235957*($A$22+273.15)-0.00000051159127*($A$22+273.15)^2-0.000000048979736*($A$22+273.15)^3)-8.31446261815324-($A$22+273.15)*8.31446261815324*(2*0.00000001*(565.620467/(($A$22+273.15)/100)^2-1202.929776/(($A$22+273.15)/100)^3+6054.858096/(($A$22+273.15)/100)^4)+($A$22+273.15)*0.0000000001*(-1131.240934/(($A$22+273.15)/100)^3+3608.789328/(($A$22+273.15)/100)^4-24219.432384/(($A$22+273.15)/100)^5))*(101325/((1+0.000001*(75.188632-565.620467/(($A$22+273.15)/100)+601.464888/(($A$22+273.15)/100)^2-2018.286032/(($A$22+273.15)/100)^3)*101325/(8.31446261815324*($A$22+273.15)))*8.31446261815324*($A$22+273.15))))) -> 1.2877244 | J22: =0.00000100697*SQRT(($A$22+273.15))/EXP(0.235156-0.491266*LN(($A$22+273.15)/251.196)+0.05211155*LN(($A$22+273.15)/251.196)^2+0.05347906*LN(($A$22+273.15)/251.196)^3-0.01537102*LN(($A$22+273.15)/251.196)^4)*1000000 -> 15.528103 | K22: =0.001*(-2.8088692+0.053424539*($A$22+273.15)+0.000038923913*($A$22+273.15)^2)*1000 -> 17.543755 | L22: =((($A$22+273.15)*0.00000001*(565.620467/(($A$22+273.15)/100)^2-1202.929776/(($A$22+273.15)/100)^3+6054.858096/(($A$22+273.15)/100)^4))-(0.000001*(75.188632-565.620467/(($A$22+273.15)/100)+601.464888/(($A$22+273.15)/100)^2-2018.286032/(($A$22+273.15)/100)^3)))/(20.823075+0.059235957*($A$22+273.15)-0.00000051159127*($A$22+273.15)^2-0.000000048979736*($A$22+273.15)^3)*100000 -> 0.98465053
